{"uid":"1f319410b2b96c60","name":"User creates the profile with incorrect data","fullName":"tests.test_users.test_create_user.TestCreateUser#test_create_user_with_incorrect_data","historyId":"dd15721ec6070036fb2feb661d7e8143","time":{"start":1756229239813,"stop":1756229239818,"duration":5},"status":"broken","statusMessage":"httpx.ConnectError: [Errno 111] Connection refused","statusTrace":"@contextlib.contextmanager\n    def map_httpcore_exceptions() -> typing.Iterator[None]:\n        global HTTPCORE_EXC_MAP\n        if len(HTTPCORE_EXC_MAP) == 0:\n            HTTPCORE_EXC_MAP = _load_httpcore_exceptions()\n        try:\n>           yield\n\n/opt/hostedtoolcache/Python/3.13.7/x64/lib/python3.13/site-packages/httpx/_transports/default.py:101: \n_ _ _ _ _ _ _ _ _ _ _ _ _ _ _ _ _ _ _ _ _ _ _ _ _ _ _ _ _ _ _ _ _ _ _ _ _ _ _ _ \n/opt/hostedtoolcache/Python/3.13.7/x64/lib/python3.13/site-packages/httpx/_transports/default.py:250: in handle_request\n    resp = self._pool.handle_request(req)\n           ^^^^^^^^^^^^^^^^^^^^^^^^^^^^^^\n/opt/hostedtoolcache/Python/3.13.7/x64/lib/python3.13/site-packages/httpcore/_sync/connection_pool.py:256: in handle_request\n    raise exc from None\n/opt/hostedtoolcache/Python/3.13.7/x64/lib/python3.13/site-packages/httpcore/_sync/connection_pool.py:236: in handle_request\n    response = connection.handle_request(\n/opt/hostedtoolcache/Python/3.13.7/x64/lib/python3.13/site-packages/httpcore/_sync/connection.py:101: in handle_request\n    raise exc\n/opt/hostedtoolcache/Python/3.13.7/x64/lib/python3.13/site-packages/httpcore/_sync/connection.py:78: in handle_request\n    stream = self._connect(request)\n             ^^^^^^^^^^^^^^^^^^^^^^\n/opt/hostedtoolcache/Python/3.13.7/x64/lib/python3.13/site-packages/httpcore/_sync/connection.py:124: in _connect\n    stream = self._network_backend.connect_tcp(**kwargs)\n             ^^^^^^^^^^^^^^^^^^^^^^^^^^^^^^^^^^^^^^^^^^^\n/opt/hostedtoolcache/Python/3.13.7/x64/lib/python3.13/site-packages/httpcore/_backends/sync.py:207: in connect_tcp\n    with map_exceptions(exc_map):\n         ^^^^^^^^^^^^^^^^^^^^^^^\n/opt/hostedtoolcache/Python/3.13.7/x64/lib/python3.13/contextlib.py:162: in __exit__\n    self.gen.throw(value)\n_ _ _ _ _ _ _ _ _ _ _ _ _ _ _ _ _ _ _ _ _ _ _ _ _ _ _ _ _ _ _ _ _ _ _ _ _ _ _ _ \n\nmap = {<class 'TimeoutError'>: <class 'httpcore.ConnectTimeout'>, <class 'OSError'>: <class 'httpcore.ConnectError'>}\n\n    @contextlib.contextmanager\n    def map_exceptions(map: ExceptionMapping) -> typing.Iterator[None]:\n        try:\n            yield\n        except Exception as exc:  # noqa: PIE786\n            for from_exc, to_exc in map.items():\n                if isinstance(exc, from_exc):\n>                   raise to_exc(exc) from exc\nE                   httpcore.ConnectError: [Errno 111] Connection refused\n\n/opt/hostedtoolcache/Python/3.13.7/x64/lib/python3.13/site-packages/httpcore/_exceptions.py:14: ConnectError\n\nThe above exception was the direct cause of the following exception:\n\nself = <tests.test_users.test_create_user.TestCreateUser object at 0x7f34e5b56c40>\npublic_users_client = <clients.users.public_users_client.PublicUsersClient object at 0x7f34e592da90>\nfield = 'last_name', invalid_value = '', location = 'lastName'\n\n    @allure.sub_suite(AllureStory.VALIDATE_ENTITY)\n    @allure.severity(Severity.CRITICAL)\n    @allure.story(AllureStory.VALIDATE_ENTITY)\n    @allure.title(\"User creates the profile with incorrect data\")\n    @pytest.mark.errors\n    @pytest.mark.parametrize(\"field, invalid_value, location\",\n                             [(\"password\", \"\", \"password\"), (\"last_name\", \"\", \"lastName\"),\n                              (\"first_name\", \"\", \"firstName\"), (\"middle_name\", \"\", \"middleName\")])\n    def test_create_user_with_incorrect_data(self, public_users_client: PublicUsersClient, field, invalid_value,\n                                             location):\n        request_data = {}\n        request_data[field] = invalid_value\n        request = CreateUserRequestSchema(**request_data)\n    \n>       response = public_users_client.create_user_api(request)\n                   ^^^^^^^^^^^^^^^^^^^^^^^^^^^^^^^^^^^^^^^^^^^^\n\ntests/test_users/test_create_user.py:57: \n_ _ _ _ _ _ _ _ _ _ _ _ _ _ _ _ _ _ _ _ _ _ _ _ _ _ _ _ _ _ _ _ _ _ _ _ _ _ _ _ \nclients/users/public_users_client.py:14: in create_user_api\n    return self.post(APIRoutes.USERS, json=request.model_dump(by_alias=True))\n           ^^^^^^^^^^^^^^^^^^^^^^^^^^^^^^^^^^^^^^^^^^^^^^^^^^^^^^^^^^^^^^^^^^\nclients/api_client.py:19: in post\n    return self.client.post(url, json=json, data=data, files=files)\n           ^^^^^^^^^^^^^^^^^^^^^^^^^^^^^^^^^^^^^^^^^^^^^^^^^^^^^^^^\n/opt/hostedtoolcache/Python/3.13.7/x64/lib/python3.13/site-packages/httpx/_client.py:1144: in post\n    return self.request(\n/opt/hostedtoolcache/Python/3.13.7/x64/lib/python3.13/site-packages/httpx/_client.py:825: in request\n    return self.send(request, auth=auth, follow_redirects=follow_redirects)\n           ^^^^^^^^^^^^^^^^^^^^^^^^^^^^^^^^^^^^^^^^^^^^^^^^^^^^^^^^^^^^^^^^\n/opt/hostedtoolcache/Python/3.13.7/x64/lib/python3.13/site-packages/httpx/_client.py:914: in send\n    response = self._send_handling_auth(\n/opt/hostedtoolcache/Python/3.13.7/x64/lib/python3.13/site-packages/httpx/_client.py:942: in _send_handling_auth\n    response = self._send_handling_redirects(\n/opt/hostedtoolcache/Python/3.13.7/x64/lib/python3.13/site-packages/httpx/_client.py:979: in _send_handling_redirects\n    response = self._send_single_request(request)\n               ^^^^^^^^^^^^^^^^^^^^^^^^^^^^^^^^^^\n/opt/hostedtoolcache/Python/3.13.7/x64/lib/python3.13/site-packages/httpx/_client.py:1014: in _send_single_request\n    response = transport.handle_request(request)\n               ^^^^^^^^^^^^^^^^^^^^^^^^^^^^^^^^^\n/opt/hostedtoolcache/Python/3.13.7/x64/lib/python3.13/site-packages/httpx/_transports/default.py:249: in handle_request\n    with map_httpcore_exceptions():\n         ^^^^^^^^^^^^^^^^^^^^^^^^^\n/opt/hostedtoolcache/Python/3.13.7/x64/lib/python3.13/contextlib.py:162: in __exit__\n    self.gen.throw(value)\n_ _ _ _ _ _ _ _ _ _ _ _ _ _ _ _ _ _ _ _ _ _ _ _ _ _ _ _ _ _ _ _ _ _ _ _ _ _ _ _ \n\n    @contextlib.contextmanager\n    def map_httpcore_exceptions() -> typing.Iterator[None]:\n        global HTTPCORE_EXC_MAP\n        if len(HTTPCORE_EXC_MAP) == 0:\n            HTTPCORE_EXC_MAP = _load_httpcore_exceptions()\n        try:\n            yield\n        except Exception as exc:\n            mapped_exc = None\n    \n            for from_exc, to_exc in HTTPCORE_EXC_MAP.items():\n                if not isinstance(exc, from_exc):\n                    continue\n                # We want to map to the most specific exception we can find.\n                # Eg if `exc` is an `httpcore.ReadTimeout`, we want to map to\n                # `httpx.ReadTimeout`, not just `httpx.TimeoutException`.\n                if mapped_exc is None or issubclass(to_exc, mapped_exc):\n                    mapped_exc = to_exc\n    \n            if mapped_exc is None:  # pragma: no cover\n                raise\n    \n            message = str(exc)\n>           raise mapped_exc(message) from exc\nE           httpx.ConnectError: [Errno 111] Connection refused\n\n/opt/hostedtoolcache/Python/3.13.7/x64/lib/python3.13/site-packages/httpx/_transports/default.py:118: ConnectError","flaky":false,"newFailed":false,"newBroken":false,"newPassed":false,"retriesCount":0,"retriesStatusChange":false,"beforeStages":[{"name":"_session_faker","time":{"start":1756229229904,"stop":1756229229959,"duration":55},"status":"passed","steps":[],"attachments":[],"parameters":[],"stepsCount":0,"shouldDisplayMessage":false,"attachmentsCount":0,"hasContent":false,"attachmentStep":false},{"name":"save_allure_environment_file","time":{"start":1756229229959,"stop":1756229229959,"duration":0},"status":"passed","steps":[],"attachments":[],"parameters":[],"stepsCount":0,"shouldDisplayMessage":false,"attachmentsCount":0,"hasContent":false,"attachmentStep":false},{"name":"public_users_client","time":{"start":1756229239789,"stop":1756229239812,"duration":23},"status":"passed","steps":[],"attachments":[],"parameters":[],"stepsCount":0,"shouldDisplayMessage":false,"attachmentsCount":0,"hasContent":false,"attachmentStep":false}],"testStage":{"status":"broken","statusMessage":"httpx.ConnectError: [Errno 111] Connection refused","statusTrace":"@contextlib.contextmanager\n    def map_httpcore_exceptions() -> typing.Iterator[None]:\n        global HTTPCORE_EXC_MAP\n        if len(HTTPCORE_EXC_MAP) == 0:\n            HTTPCORE_EXC_MAP = _load_httpcore_exceptions()\n        try:\n>           yield\n\n/opt/hostedtoolcache/Python/3.13.7/x64/lib/python3.13/site-packages/httpx/_transports/default.py:101: \n_ _ _ _ _ _ _ _ _ _ _ _ _ _ _ _ _ _ _ _ _ _ _ _ _ _ _ _ _ _ _ _ _ _ _ _ _ _ _ _ \n/opt/hostedtoolcache/Python/3.13.7/x64/lib/python3.13/site-packages/httpx/_transports/default.py:250: in handle_request\n    resp = self._pool.handle_request(req)\n           ^^^^^^^^^^^^^^^^^^^^^^^^^^^^^^\n/opt/hostedtoolcache/Python/3.13.7/x64/lib/python3.13/site-packages/httpcore/_sync/connection_pool.py:256: in handle_request\n    raise exc from None\n/opt/hostedtoolcache/Python/3.13.7/x64/lib/python3.13/site-packages/httpcore/_sync/connection_pool.py:236: in handle_request\n    response = connection.handle_request(\n/opt/hostedtoolcache/Python/3.13.7/x64/lib/python3.13/site-packages/httpcore/_sync/connection.py:101: in handle_request\n    raise exc\n/opt/hostedtoolcache/Python/3.13.7/x64/lib/python3.13/site-packages/httpcore/_sync/connection.py:78: in handle_request\n    stream = self._connect(request)\n             ^^^^^^^^^^^^^^^^^^^^^^\n/opt/hostedtoolcache/Python/3.13.7/x64/lib/python3.13/site-packages/httpcore/_sync/connection.py:124: in _connect\n    stream = self._network_backend.connect_tcp(**kwargs)\n             ^^^^^^^^^^^^^^^^^^^^^^^^^^^^^^^^^^^^^^^^^^^\n/opt/hostedtoolcache/Python/3.13.7/x64/lib/python3.13/site-packages/httpcore/_backends/sync.py:207: in connect_tcp\n    with map_exceptions(exc_map):\n         ^^^^^^^^^^^^^^^^^^^^^^^\n/opt/hostedtoolcache/Python/3.13.7/x64/lib/python3.13/contextlib.py:162: in __exit__\n    self.gen.throw(value)\n_ _ _ _ _ _ _ _ _ _ _ _ _ _ _ _ _ _ _ _ _ _ _ _ _ _ _ _ _ _ _ _ _ _ _ _ _ _ _ _ \n\nmap = {<class 'TimeoutError'>: <class 'httpcore.ConnectTimeout'>, <class 'OSError'>: <class 'httpcore.ConnectError'>}\n\n    @contextlib.contextmanager\n    def map_exceptions(map: ExceptionMapping) -> typing.Iterator[None]:\n        try:\n            yield\n        except Exception as exc:  # noqa: PIE786\n            for from_exc, to_exc in map.items():\n                if isinstance(exc, from_exc):\n>                   raise to_exc(exc) from exc\nE                   httpcore.ConnectError: [Errno 111] Connection refused\n\n/opt/hostedtoolcache/Python/3.13.7/x64/lib/python3.13/site-packages/httpcore/_exceptions.py:14: ConnectError\n\nThe above exception was the direct cause of the following exception:\n\nself = <tests.test_users.test_create_user.TestCreateUser object at 0x7f34e5b56c40>\npublic_users_client = <clients.users.public_users_client.PublicUsersClient object at 0x7f34e592da90>\nfield = 'last_name', invalid_value = '', location = 'lastName'\n\n    @allure.sub_suite(AllureStory.VALIDATE_ENTITY)\n    @allure.severity(Severity.CRITICAL)\n    @allure.story(AllureStory.VALIDATE_ENTITY)\n    @allure.title(\"User creates the profile with incorrect data\")\n    @pytest.mark.errors\n    @pytest.mark.parametrize(\"field, invalid_value, location\",\n                             [(\"password\", \"\", \"password\"), (\"last_name\", \"\", \"lastName\"),\n                              (\"first_name\", \"\", \"firstName\"), (\"middle_name\", \"\", \"middleName\")])\n    def test_create_user_with_incorrect_data(self, public_users_client: PublicUsersClient, field, invalid_value,\n                                             location):\n        request_data = {}\n        request_data[field] = invalid_value\n        request = CreateUserRequestSchema(**request_data)\n    \n>       response = public_users_client.create_user_api(request)\n                   ^^^^^^^^^^^^^^^^^^^^^^^^^^^^^^^^^^^^^^^^^^^^\n\ntests/test_users/test_create_user.py:57: \n_ _ _ _ _ _ _ _ _ _ _ _ _ _ _ _ _ _ _ _ _ _ _ _ _ _ _ _ _ _ _ _ _ _ _ _ _ _ _ _ \nclients/users/public_users_client.py:14: in create_user_api\n    return self.post(APIRoutes.USERS, json=request.model_dump(by_alias=True))\n           ^^^^^^^^^^^^^^^^^^^^^^^^^^^^^^^^^^^^^^^^^^^^^^^^^^^^^^^^^^^^^^^^^^\nclients/api_client.py:19: in post\n    return self.client.post(url, json=json, data=data, files=files)\n           ^^^^^^^^^^^^^^^^^^^^^^^^^^^^^^^^^^^^^^^^^^^^^^^^^^^^^^^^\n/opt/hostedtoolcache/Python/3.13.7/x64/lib/python3.13/site-packages/httpx/_client.py:1144: in post\n    return self.request(\n/opt/hostedtoolcache/Python/3.13.7/x64/lib/python3.13/site-packages/httpx/_client.py:825: in request\n    return self.send(request, auth=auth, follow_redirects=follow_redirects)\n           ^^^^^^^^^^^^^^^^^^^^^^^^^^^^^^^^^^^^^^^^^^^^^^^^^^^^^^^^^^^^^^^^\n/opt/hostedtoolcache/Python/3.13.7/x64/lib/python3.13/site-packages/httpx/_client.py:914: in send\n    response = self._send_handling_auth(\n/opt/hostedtoolcache/Python/3.13.7/x64/lib/python3.13/site-packages/httpx/_client.py:942: in _send_handling_auth\n    response = self._send_handling_redirects(\n/opt/hostedtoolcache/Python/3.13.7/x64/lib/python3.13/site-packages/httpx/_client.py:979: in _send_handling_redirects\n    response = self._send_single_request(request)\n               ^^^^^^^^^^^^^^^^^^^^^^^^^^^^^^^^^^\n/opt/hostedtoolcache/Python/3.13.7/x64/lib/python3.13/site-packages/httpx/_client.py:1014: in _send_single_request\n    response = transport.handle_request(request)\n               ^^^^^^^^^^^^^^^^^^^^^^^^^^^^^^^^^\n/opt/hostedtoolcache/Python/3.13.7/x64/lib/python3.13/site-packages/httpx/_transports/default.py:249: in handle_request\n    with map_httpcore_exceptions():\n         ^^^^^^^^^^^^^^^^^^^^^^^^^\n/opt/hostedtoolcache/Python/3.13.7/x64/lib/python3.13/contextlib.py:162: in __exit__\n    self.gen.throw(value)\n_ _ _ _ _ _ _ _ _ _ _ _ _ _ _ _ _ _ _ _ _ _ _ _ _ _ _ _ _ _ _ _ _ _ _ _ _ _ _ _ \n\n    @contextlib.contextmanager\n    def map_httpcore_exceptions() -> typing.Iterator[None]:\n        global HTTPCORE_EXC_MAP\n        if len(HTTPCORE_EXC_MAP) == 0:\n            HTTPCORE_EXC_MAP = _load_httpcore_exceptions()\n        try:\n            yield\n        except Exception as exc:\n            mapped_exc = None\n    \n            for from_exc, to_exc in HTTPCORE_EXC_MAP.items():\n                if not isinstance(exc, from_exc):\n                    continue\n                # We want to map to the most specific exception we can find.\n                # Eg if `exc` is an `httpcore.ReadTimeout`, we want to map to\n                # `httpx.ReadTimeout`, not just `httpx.TimeoutException`.\n                if mapped_exc is None or issubclass(to_exc, mapped_exc):\n                    mapped_exc = to_exc\n    \n            if mapped_exc is None:  # pragma: no cover\n                raise\n    \n            message = str(exc)\n>           raise mapped_exc(message) from exc\nE           httpx.ConnectError: [Errno 111] Connection refused\n\n/opt/hostedtoolcache/Python/3.13.7/x64/lib/python3.13/site-packages/httpx/_transports/default.py:118: ConnectError","steps":[{"name":"Create user","time":{"start":1756229239814,"stop":1756229239816,"duration":2},"status":"broken","statusMessage":"httpx.ConnectError: [Errno 111] Connection refused\n","statusTrace":"  File \"/opt/hostedtoolcache/Python/3.13.7/x64/lib/python3.13/site-packages/allure_commons/_allure.py\", line 202, in impl\n    return func(*a, **kw)\n  File \"/home/runner/work/api_autotests/api_autotests/clients/users/public_users_client.py\", line 14, in create_user_api\n    return self.post(APIRoutes.USERS, json=request.model_dump(by_alias=True))\n           ~~~~~~~~~^^^^^^^^^^^^^^^^^^^^^^^^^^^^^^^^^^^^^^^^^^^^^^^^^^^^^^^^^\n  File \"/opt/hostedtoolcache/Python/3.13.7/x64/lib/python3.13/site-packages/allure_commons/_allure.py\", line 202, in impl\n    return func(*a, **kw)\n  File \"/home/runner/work/api_autotests/api_autotests/clients/api_client.py\", line 19, in post\n    return self.client.post(url, json=json, data=data, files=files)\n           ~~~~~~~~~~~~~~~~^^^^^^^^^^^^^^^^^^^^^^^^^^^^^^^^^^^^^^^^\n  File \"/opt/hostedtoolcache/Python/3.13.7/x64/lib/python3.13/site-packages/httpx/_client.py\", line 1144, in post\n    return self.request(\n           ~~~~~~~~~~~~^\n        \"POST\",\n        ^^^^^^^\n    ...<11 lines>...\n        extensions=extensions,\n        ^^^^^^^^^^^^^^^^^^^^^^\n    )\n    ^\n  File \"/opt/hostedtoolcache/Python/3.13.7/x64/lib/python3.13/site-packages/httpx/_client.py\", line 825, in request\n    return self.send(request, auth=auth, follow_redirects=follow_redirects)\n           ~~~~~~~~~^^^^^^^^^^^^^^^^^^^^^^^^^^^^^^^^^^^^^^^^^^^^^^^^^^^^^^^\n  File \"/opt/hostedtoolcache/Python/3.13.7/x64/lib/python3.13/site-packages/httpx/_client.py\", line 914, in send\n    response = self._send_handling_auth(\n        request,\n    ...<2 lines>...\n        history=[],\n    )\n  File \"/opt/hostedtoolcache/Python/3.13.7/x64/lib/python3.13/site-packages/httpx/_client.py\", line 942, in _send_handling_auth\n    response = self._send_handling_redirects(\n        request,\n        follow_redirects=follow_redirects,\n        history=history,\n    )\n  File \"/opt/hostedtoolcache/Python/3.13.7/x64/lib/python3.13/site-packages/httpx/_client.py\", line 979, in _send_handling_redirects\n    response = self._send_single_request(request)\n  File \"/opt/hostedtoolcache/Python/3.13.7/x64/lib/python3.13/site-packages/httpx/_client.py\", line 1014, in _send_single_request\n    response = transport.handle_request(request)\n  File \"/opt/hostedtoolcache/Python/3.13.7/x64/lib/python3.13/site-packages/httpx/_transports/default.py\", line 249, in handle_request\n    with map_httpcore_exceptions():\n         ~~~~~~~~~~~~~~~~~~~~~~~^^\n  File \"/opt/hostedtoolcache/Python/3.13.7/x64/lib/python3.13/contextlib.py\", line 162, in __exit__\n    self.gen.throw(value)\n    ~~~~~~~~~~~~~~^^^^^^^\n  File \"/opt/hostedtoolcache/Python/3.13.7/x64/lib/python3.13/site-packages/httpx/_transports/default.py\", line 118, in map_httpcore_exceptions\n    raise mapped_exc(message) from exc\n","steps":[{"name":"Make POST request to '/api/v1/users'","time":{"start":1756229239814,"stop":1756229239815,"duration":1},"status":"broken","statusMessage":"httpx.ConnectError: [Errno 111] Connection refused\n","statusTrace":"  File \"/opt/hostedtoolcache/Python/3.13.7/x64/lib/python3.13/site-packages/allure_commons/_allure.py\", line 202, in impl\n    return func(*a, **kw)\n  File \"/home/runner/work/api_autotests/api_autotests/clients/api_client.py\", line 19, in post\n    return self.client.post(url, json=json, data=data, files=files)\n           ~~~~~~~~~~~~~~~~^^^^^^^^^^^^^^^^^^^^^^^^^^^^^^^^^^^^^^^^\n  File \"/opt/hostedtoolcache/Python/3.13.7/x64/lib/python3.13/site-packages/httpx/_client.py\", line 1144, in post\n    return self.request(\n           ~~~~~~~~~~~~^\n        \"POST\",\n        ^^^^^^^\n    ...<11 lines>...\n        extensions=extensions,\n        ^^^^^^^^^^^^^^^^^^^^^^\n    )\n    ^\n  File \"/opt/hostedtoolcache/Python/3.13.7/x64/lib/python3.13/site-packages/httpx/_client.py\", line 825, in request\n    return self.send(request, auth=auth, follow_redirects=follow_redirects)\n           ~~~~~~~~~^^^^^^^^^^^^^^^^^^^^^^^^^^^^^^^^^^^^^^^^^^^^^^^^^^^^^^^\n  File \"/opt/hostedtoolcache/Python/3.13.7/x64/lib/python3.13/site-packages/httpx/_client.py\", line 914, in send\n    response = self._send_handling_auth(\n        request,\n    ...<2 lines>...\n        history=[],\n    )\n  File \"/opt/hostedtoolcache/Python/3.13.7/x64/lib/python3.13/site-packages/httpx/_client.py\", line 942, in _send_handling_auth\n    response = self._send_handling_redirects(\n        request,\n        follow_redirects=follow_redirects,\n        history=history,\n    )\n  File \"/opt/hostedtoolcache/Python/3.13.7/x64/lib/python3.13/site-packages/httpx/_client.py\", line 979, in _send_handling_redirects\n    response = self._send_single_request(request)\n  File \"/opt/hostedtoolcache/Python/3.13.7/x64/lib/python3.13/site-packages/httpx/_client.py\", line 1014, in _send_single_request\n    response = transport.handle_request(request)\n  File \"/opt/hostedtoolcache/Python/3.13.7/x64/lib/python3.13/site-packages/httpx/_transports/default.py\", line 249, in handle_request\n    with map_httpcore_exceptions():\n         ~~~~~~~~~~~~~~~~~~~~~~~^^\n  File \"/opt/hostedtoolcache/Python/3.13.7/x64/lib/python3.13/contextlib.py\", line 162, in __exit__\n    self.gen.throw(value)\n    ~~~~~~~~~~~~~~^^^^^^^\n  File \"/opt/hostedtoolcache/Python/3.13.7/x64/lib/python3.13/site-packages/httpx/_transports/default.py\", line 118, in map_httpcore_exceptions\n    raise mapped_exc(message) from exc\n","steps":[],"attachments":[{"uid":"f166d2883d52ef37","name":"cURL command","source":"f166d2883d52ef37.txt","type":"text/plain","size":436}],"parameters":[{"name":"url","value":"'/api/v1/users'"},{"name":"json","value":"{'email': 'boleslav_38@example.com', 'password': '+A475Jgi&x', 'lastName': '', 'firstName': 'Феоктист', 'middleName': 'Данилович'}"},{"name":"data","value":"None"},{"name":"files","value":"None"}],"stepsCount":0,"shouldDisplayMessage":true,"attachmentsCount":1,"hasContent":true,"attachmentStep":false}],"attachments":[],"parameters":[{"name":"request","value":"CreateUserRequestSchema(email='boleslav_38@example.com', password='+A475Jgi&x', last_name='', first_name='Феоктист', middle_name='Данилович')"}],"stepsCount":1,"shouldDisplayMessage":false,"attachmentsCount":1,"hasContent":true,"attachmentStep":false}],"attachments":[{"uid":"c0003c07dc530d47","name":"log","source":"c0003c07dc530d47.txt","type":"text/plain","size":94}],"parameters":[],"stepsCount":2,"shouldDisplayMessage":true,"attachmentsCount":2,"hasContent":true,"attachmentStep":false},"afterStages":[{"name":"save_allure_environment_file::0","time":{"start":1756229240636,"stop":1756229240637,"duration":1},"status":"passed","steps":[],"attachments":[],"parameters":[],"stepsCount":0,"shouldDisplayMessage":false,"attachmentsCount":0,"hasContent":false,"attachmentStep":false}],"labels":[{"name":"epic","value":"LMS service"},{"name":"parentSuite","value":"LMS service"},{"name":"suite","value":"Users"},{"name":"subSuite","value":"Validate entity"},{"name":"severity","value":"critical"},{"name":"story","value":"Validate entity"},{"name":"feature","value":"Users"},{"name":"tag","value":"errors"},{"name":"tag","value":"regression"},{"name":"tag","value":"users"},{"name":"tag","value":"create"},{"name":"host","value":"pkrvmqc4gcfdwos"},{"name":"thread","value":"2409-MainThread"},{"name":"framework","value":"pytest"},{"name":"language","value":"cpython3"},{"name":"package","value":"tests.test_users.test_create_user"},{"name":"resultFormat","value":"allure2"}],"parameters":[{"name":"field","value":"'last_name'"},{"name":"invalid_value","value":"''"},{"name":"location","value":"'lastName'"}],"links":[],"hidden":false,"retry":false,"extra":{"severity":"critical","retries":[],"categories":[{"name":"Test defects","matchedStatuses":[],"flaky":false}],"history":{"statistic":{"failed":0,"broken":5,"skipped":0,"passed":0,"unknown":0,"total":5},"items":[{"uid":"e81b36386efa89b","reportUrl":"https://bogdanshcherban8.github.io/api_autotests/4/#testresult/e81b36386efa89b","status":"broken","statusDetails":"httpx.ConnectError: [Errno 111] Connection refused","time":{"start":1756228916337,"stop":1756228916345,"duration":8}},{"uid":"10476a3971aca522","reportUrl":"https://bogdanshcherban8.github.io/api_autotests/3/#testresult/10476a3971aca522","status":"broken","statusDetails":"httpx.ConnectError: [Errno -3] Temporary failure in name resolution","time":{"start":1756228636828,"stop":1756228636834,"duration":6}},{"uid":"d75f51ca9ad8db19","reportUrl":"https://bogdanshcherban8.github.io/api_autotests/2/#testresult/d75f51ca9ad8db19","status":"broken","statusDetails":"httpx.ConnectError: [Errno -3] Temporary failure in name resolution","time":{"start":1756228281671,"stop":1756228281679,"duration":8}},{"uid":"678328c7c6b28dab","reportUrl":"https://bogdanshcherban8.github.io/api_autotests/1/#testresult/678328c7c6b28dab","status":"broken","statusDetails":"httpx.ConnectError: [Errno 111] Connection refused","time":{"start":1756227882669,"stop":1756227882675,"duration":6}}]},"tags":["regression","create","errors","users"]},"source":"1f319410b2b96c60.json","parameterValues":["'last_name'","''","'lastName'"]}