{"uid":"b7dcc3a466b916fe","name":"User deletes the profile with incorrect user_id","fullName":"tests.test_users.test_delete_user.TestDeleteUser#test_delete_user_with_incorrect_data","historyId":"20481126ee96910e30dd31ffdf2a25e4","time":{"start":1756229240074,"stop":1756229240074,"duration":0},"status":"broken","statusMessage":"httpx.ConnectError: [Errno 111] Connection refused","statusTrace":"@contextlib.contextmanager\n    def map_httpcore_exceptions() -> typing.Iterator[None]:\n        global HTTPCORE_EXC_MAP\n        if len(HTTPCORE_EXC_MAP) == 0:\n            HTTPCORE_EXC_MAP = _load_httpcore_exceptions()\n        try:\n>           yield\n\n/opt/hostedtoolcache/Python/3.13.7/x64/lib/python3.13/site-packages/httpx/_transports/default.py:101: \n_ _ _ _ _ _ _ _ _ _ _ _ _ _ _ _ _ _ _ _ _ _ _ _ _ _ _ _ _ _ _ _ _ _ _ _ _ _ _ _ \n/opt/hostedtoolcache/Python/3.13.7/x64/lib/python3.13/site-packages/httpx/_transports/default.py:250: in handle_request\n    resp = self._pool.handle_request(req)\n           ^^^^^^^^^^^^^^^^^^^^^^^^^^^^^^\n/opt/hostedtoolcache/Python/3.13.7/x64/lib/python3.13/site-packages/httpcore/_sync/connection_pool.py:256: in handle_request\n    raise exc from None\n/opt/hostedtoolcache/Python/3.13.7/x64/lib/python3.13/site-packages/httpcore/_sync/connection_pool.py:236: in handle_request\n    response = connection.handle_request(\n/opt/hostedtoolcache/Python/3.13.7/x64/lib/python3.13/site-packages/httpcore/_sync/connection.py:101: in handle_request\n    raise exc\n/opt/hostedtoolcache/Python/3.13.7/x64/lib/python3.13/site-packages/httpcore/_sync/connection.py:78: in handle_request\n    stream = self._connect(request)\n             ^^^^^^^^^^^^^^^^^^^^^^\n/opt/hostedtoolcache/Python/3.13.7/x64/lib/python3.13/site-packages/httpcore/_sync/connection.py:124: in _connect\n    stream = self._network_backend.connect_tcp(**kwargs)\n             ^^^^^^^^^^^^^^^^^^^^^^^^^^^^^^^^^^^^^^^^^^^\n/opt/hostedtoolcache/Python/3.13.7/x64/lib/python3.13/site-packages/httpcore/_backends/sync.py:207: in connect_tcp\n    with map_exceptions(exc_map):\n         ^^^^^^^^^^^^^^^^^^^^^^^\n/opt/hostedtoolcache/Python/3.13.7/x64/lib/python3.13/contextlib.py:162: in __exit__\n    self.gen.throw(value)\n_ _ _ _ _ _ _ _ _ _ _ _ _ _ _ _ _ _ _ _ _ _ _ _ _ _ _ _ _ _ _ _ _ _ _ _ _ _ _ _ \n\nmap = {<class 'TimeoutError'>: <class 'httpcore.ConnectTimeout'>, <class 'OSError'>: <class 'httpcore.ConnectError'>}\n\n    @contextlib.contextmanager\n    def map_exceptions(map: ExceptionMapping) -> typing.Iterator[None]:\n        try:\n            yield\n        except Exception as exc:  # noqa: PIE786\n            for from_exc, to_exc in map.items():\n                if isinstance(exc, from_exc):\n>                   raise to_exc(exc) from exc\nE                   httpcore.ConnectError: [Errno 111] Connection refused\n\n/opt/hostedtoolcache/Python/3.13.7/x64/lib/python3.13/site-packages/httpcore/_exceptions.py:14: ConnectError\n\nThe above exception was the direct cause of the following exception:\n\npublic_users_client = <clients.users.public_users_client.PublicUsersClient object at 0x7f34e58d1a90>\n\n    @pytest.fixture\n    def create_user(public_users_client: PublicUsersClient) -> UserData:\n        request = CreateUserRequestSchema()\n>       response = public_users_client.create_user(request)\n                   ^^^^^^^^^^^^^^^^^^^^^^^^^^^^^^^^^^^^^^^^\n\nfixtures/users.py:30: \n_ _ _ _ _ _ _ _ _ _ _ _ _ _ _ _ _ _ _ _ _ _ _ _ _ _ _ _ _ _ _ _ _ _ _ _ _ _ _ _ \nclients/users/public_users_client.py:17: in create_user\n    response = self.create_user_api(request)\n               ^^^^^^^^^^^^^^^^^^^^^^^^^^^^^\nclients/users/public_users_client.py:14: in create_user_api\n    return self.post(APIRoutes.USERS, json=request.model_dump(by_alias=True))\n           ^^^^^^^^^^^^^^^^^^^^^^^^^^^^^^^^^^^^^^^^^^^^^^^^^^^^^^^^^^^^^^^^^^\nclients/api_client.py:19: in post\n    return self.client.post(url, json=json, data=data, files=files)\n           ^^^^^^^^^^^^^^^^^^^^^^^^^^^^^^^^^^^^^^^^^^^^^^^^^^^^^^^^\n/opt/hostedtoolcache/Python/3.13.7/x64/lib/python3.13/site-packages/httpx/_client.py:1144: in post\n    return self.request(\n/opt/hostedtoolcache/Python/3.13.7/x64/lib/python3.13/site-packages/httpx/_client.py:825: in request\n    return self.send(request, auth=auth, follow_redirects=follow_redirects)\n           ^^^^^^^^^^^^^^^^^^^^^^^^^^^^^^^^^^^^^^^^^^^^^^^^^^^^^^^^^^^^^^^^\n/opt/hostedtoolcache/Python/3.13.7/x64/lib/python3.13/site-packages/httpx/_client.py:914: in send\n    response = self._send_handling_auth(\n/opt/hostedtoolcache/Python/3.13.7/x64/lib/python3.13/site-packages/httpx/_client.py:942: in _send_handling_auth\n    response = self._send_handling_redirects(\n/opt/hostedtoolcache/Python/3.13.7/x64/lib/python3.13/site-packages/httpx/_client.py:979: in _send_handling_redirects\n    response = self._send_single_request(request)\n               ^^^^^^^^^^^^^^^^^^^^^^^^^^^^^^^^^^\n/opt/hostedtoolcache/Python/3.13.7/x64/lib/python3.13/site-packages/httpx/_client.py:1014: in _send_single_request\n    response = transport.handle_request(request)\n               ^^^^^^^^^^^^^^^^^^^^^^^^^^^^^^^^^\n/opt/hostedtoolcache/Python/3.13.7/x64/lib/python3.13/site-packages/httpx/_transports/default.py:249: in handle_request\n    with map_httpcore_exceptions():\n         ^^^^^^^^^^^^^^^^^^^^^^^^^\n/opt/hostedtoolcache/Python/3.13.7/x64/lib/python3.13/contextlib.py:162: in __exit__\n    self.gen.throw(value)\n_ _ _ _ _ _ _ _ _ _ _ _ _ _ _ _ _ _ _ _ _ _ _ _ _ _ _ _ _ _ _ _ _ _ _ _ _ _ _ _ \n\n    @contextlib.contextmanager\n    def map_httpcore_exceptions() -> typing.Iterator[None]:\n        global HTTPCORE_EXC_MAP\n        if len(HTTPCORE_EXC_MAP) == 0:\n            HTTPCORE_EXC_MAP = _load_httpcore_exceptions()\n        try:\n            yield\n        except Exception as exc:\n            mapped_exc = None\n    \n            for from_exc, to_exc in HTTPCORE_EXC_MAP.items():\n                if not isinstance(exc, from_exc):\n                    continue\n                # We want to map to the most specific exception we can find.\n                # Eg if `exc` is an `httpcore.ReadTimeout`, we want to map to\n                # `httpx.ReadTimeout`, not just `httpx.TimeoutException`.\n                if mapped_exc is None or issubclass(to_exc, mapped_exc):\n                    mapped_exc = to_exc\n    \n            if mapped_exc is None:  # pragma: no cover\n                raise\n    \n            message = str(exc)\n>           raise mapped_exc(message) from exc\nE           httpx.ConnectError: [Errno 111] Connection refused\n\n/opt/hostedtoolcache/Python/3.13.7/x64/lib/python3.13/site-packages/httpx/_transports/default.py:118: ConnectError","flaky":false,"newFailed":false,"newBroken":false,"newPassed":false,"retriesCount":0,"retriesStatusChange":false,"beforeStages":[{"name":"_session_faker","time":{"start":1756229229904,"stop":1756229229959,"duration":55},"status":"passed","steps":[],"attachments":[],"parameters":[],"stepsCount":0,"shouldDisplayMessage":false,"attachmentsCount":0,"hasContent":false,"attachmentStep":false},{"name":"save_allure_environment_file","time":{"start":1756229229959,"stop":1756229229959,"duration":0},"status":"passed","steps":[],"attachments":[],"parameters":[],"stepsCount":0,"shouldDisplayMessage":false,"attachmentsCount":0,"hasContent":false,"attachmentStep":false},{"name":"public_users_client","time":{"start":1756229240075,"stop":1756229240096,"duration":21},"status":"passed","steps":[],"attachments":[],"parameters":[],"stepsCount":0,"shouldDisplayMessage":false,"attachmentsCount":0,"hasContent":false,"attachmentStep":false},{"name":"create_user","time":{"start":1756229240096,"stop":1756229240101,"duration":5},"status":"broken","statusMessage":"httpx.ConnectError: [Errno 111] Connection refused\n","statusTrace":"  File \"/opt/hostedtoolcache/Python/3.13.7/x64/lib/python3.13/site-packages/pluggy/_callers.py\", line 38, in run_old_style_hookwrapper\n    res = yield\n          ^^^^^\n  File \"/opt/hostedtoolcache/Python/3.13.7/x64/lib/python3.13/site-packages/pluggy/_callers.py\", line 139, in _multicall\n    teardown.throw(exception)\n    ~~~~~~~~~~~~~~^^^^^^^^^^^\n  File \"/opt/hostedtoolcache/Python/3.13.7/x64/lib/python3.13/site-packages/pluggy/_callers.py\", line 53, in run_old_style_hookwrapper\n    return result.get_result()\n           ~~~~~~~~~~~~~~~~~^^\n  File \"/opt/hostedtoolcache/Python/3.13.7/x64/lib/python3.13/site-packages/pluggy/_result.py\", line 103, in get_result\n    raise exc.with_traceback(tb)\n  File \"/opt/hostedtoolcache/Python/3.13.7/x64/lib/python3.13/site-packages/pluggy/_callers.py\", line 38, in run_old_style_hookwrapper\n    res = yield\n          ^^^^^\n  File \"/opt/hostedtoolcache/Python/3.13.7/x64/lib/python3.13/site-packages/pluggy/_callers.py\", line 139, in _multicall\n    teardown.throw(exception)\n    ~~~~~~~~~~~~~~^^^^^^^^^^^\n  File \"/opt/hostedtoolcache/Python/3.13.7/x64/lib/python3.13/site-packages/_pytest/setuponly.py\", line 36, in pytest_fixture_setup\n    return (yield)\n            ^^^^^\n  File \"/opt/hostedtoolcache/Python/3.13.7/x64/lib/python3.13/site-packages/pluggy/_callers.py\", line 121, in _multicall\n    res = hook_impl.function(*args)\n  File \"/opt/hostedtoolcache/Python/3.13.7/x64/lib/python3.13/site-packages/_pytest/fixtures.py\", line 1195, in pytest_fixture_setup\n    result = call_fixture_func(fixturefunc, request, kwargs)\n  File \"/opt/hostedtoolcache/Python/3.13.7/x64/lib/python3.13/site-packages/_pytest/fixtures.py\", line 929, in call_fixture_func\n    fixture_result = fixturefunc(**kwargs)\n  File \"/home/runner/work/api_autotests/api_autotests/fixtures/users.py\", line 30, in create_user\n    response = public_users_client.create_user(request)\n  File \"/home/runner/work/api_autotests/api_autotests/clients/users/public_users_client.py\", line 17, in create_user\n    response = self.create_user_api(request)\n  File \"/opt/hostedtoolcache/Python/3.13.7/x64/lib/python3.13/site-packages/allure_commons/_allure.py\", line 202, in impl\n    return func(*a, **kw)\n  File \"/home/runner/work/api_autotests/api_autotests/clients/users/public_users_client.py\", line 14, in create_user_api\n    return self.post(APIRoutes.USERS, json=request.model_dump(by_alias=True))\n           ~~~~~~~~~^^^^^^^^^^^^^^^^^^^^^^^^^^^^^^^^^^^^^^^^^^^^^^^^^^^^^^^^^\n  File \"/opt/hostedtoolcache/Python/3.13.7/x64/lib/python3.13/site-packages/allure_commons/_allure.py\", line 202, in impl\n    return func(*a, **kw)\n  File \"/home/runner/work/api_autotests/api_autotests/clients/api_client.py\", line 19, in post\n    return self.client.post(url, json=json, data=data, files=files)\n           ~~~~~~~~~~~~~~~~^^^^^^^^^^^^^^^^^^^^^^^^^^^^^^^^^^^^^^^^\n  File \"/opt/hostedtoolcache/Python/3.13.7/x64/lib/python3.13/site-packages/httpx/_client.py\", line 1144, in post\n    return self.request(\n           ~~~~~~~~~~~~^\n        \"POST\",\n        ^^^^^^^\n    ...<11 lines>...\n        extensions=extensions,\n        ^^^^^^^^^^^^^^^^^^^^^^\n    )\n    ^\n  File \"/opt/hostedtoolcache/Python/3.13.7/x64/lib/python3.13/site-packages/httpx/_client.py\", line 825, in request\n    return self.send(request, auth=auth, follow_redirects=follow_redirects)\n           ~~~~~~~~~^^^^^^^^^^^^^^^^^^^^^^^^^^^^^^^^^^^^^^^^^^^^^^^^^^^^^^^\n  File \"/opt/hostedtoolcache/Python/3.13.7/x64/lib/python3.13/site-packages/httpx/_client.py\", line 914, in send\n    response = self._send_handling_auth(\n        request,\n    ...<2 lines>...\n        history=[],\n    )\n  File \"/opt/hostedtoolcache/Python/3.13.7/x64/lib/python3.13/site-packages/httpx/_client.py\", line 942, in _send_handling_auth\n    response = self._send_handling_redirects(\n        request,\n        follow_redirects=follow_redirects,\n        history=history,\n    )\n  File \"/opt/hostedtoolcache/Python/3.13.7/x64/lib/python3.13/site-packages/httpx/_client.py\", line 979, in _send_handling_redirects\n    response = self._send_single_request(request)\n  File \"/opt/hostedtoolcache/Python/3.13.7/x64/lib/python3.13/site-packages/httpx/_client.py\", line 1014, in _send_single_request\n    response = transport.handle_request(request)\n  File \"/opt/hostedtoolcache/Python/3.13.7/x64/lib/python3.13/site-packages/httpx/_transports/default.py\", line 249, in handle_request\n    with map_httpcore_exceptions():\n         ~~~~~~~~~~~~~~~~~~~~~~~^^\n  File \"/opt/hostedtoolcache/Python/3.13.7/x64/lib/python3.13/contextlib.py\", line 162, in __exit__\n    self.gen.throw(value)\n    ~~~~~~~~~~~~~~^^^^^^^\n  File \"/opt/hostedtoolcache/Python/3.13.7/x64/lib/python3.13/site-packages/httpx/_transports/default.py\", line 118, in map_httpcore_exceptions\n    raise mapped_exc(message) from exc\n","steps":[{"name":"Create user","time":{"start":1756229240096,"stop":1756229240099,"duration":3},"status":"broken","statusMessage":"httpx.ConnectError: [Errno 111] Connection refused\n","statusTrace":"  File \"/opt/hostedtoolcache/Python/3.13.7/x64/lib/python3.13/site-packages/allure_commons/_allure.py\", line 202, in impl\n    return func(*a, **kw)\n  File \"/home/runner/work/api_autotests/api_autotests/clients/users/public_users_client.py\", line 14, in create_user_api\n    return self.post(APIRoutes.USERS, json=request.model_dump(by_alias=True))\n           ~~~~~~~~~^^^^^^^^^^^^^^^^^^^^^^^^^^^^^^^^^^^^^^^^^^^^^^^^^^^^^^^^^\n  File \"/opt/hostedtoolcache/Python/3.13.7/x64/lib/python3.13/site-packages/allure_commons/_allure.py\", line 202, in impl\n    return func(*a, **kw)\n  File \"/home/runner/work/api_autotests/api_autotests/clients/api_client.py\", line 19, in post\n    return self.client.post(url, json=json, data=data, files=files)\n           ~~~~~~~~~~~~~~~~^^^^^^^^^^^^^^^^^^^^^^^^^^^^^^^^^^^^^^^^\n  File \"/opt/hostedtoolcache/Python/3.13.7/x64/lib/python3.13/site-packages/httpx/_client.py\", line 1144, in post\n    return self.request(\n           ~~~~~~~~~~~~^\n        \"POST\",\n        ^^^^^^^\n    ...<11 lines>...\n        extensions=extensions,\n        ^^^^^^^^^^^^^^^^^^^^^^\n    )\n    ^\n  File \"/opt/hostedtoolcache/Python/3.13.7/x64/lib/python3.13/site-packages/httpx/_client.py\", line 825, in request\n    return self.send(request, auth=auth, follow_redirects=follow_redirects)\n           ~~~~~~~~~^^^^^^^^^^^^^^^^^^^^^^^^^^^^^^^^^^^^^^^^^^^^^^^^^^^^^^^\n  File \"/opt/hostedtoolcache/Python/3.13.7/x64/lib/python3.13/site-packages/httpx/_client.py\", line 914, in send\n    response = self._send_handling_auth(\n        request,\n    ...<2 lines>...\n        history=[],\n    )\n  File \"/opt/hostedtoolcache/Python/3.13.7/x64/lib/python3.13/site-packages/httpx/_client.py\", line 942, in _send_handling_auth\n    response = self._send_handling_redirects(\n        request,\n        follow_redirects=follow_redirects,\n        history=history,\n    )\n  File \"/opt/hostedtoolcache/Python/3.13.7/x64/lib/python3.13/site-packages/httpx/_client.py\", line 979, in _send_handling_redirects\n    response = self._send_single_request(request)\n  File \"/opt/hostedtoolcache/Python/3.13.7/x64/lib/python3.13/site-packages/httpx/_client.py\", line 1014, in _send_single_request\n    response = transport.handle_request(request)\n  File \"/opt/hostedtoolcache/Python/3.13.7/x64/lib/python3.13/site-packages/httpx/_transports/default.py\", line 249, in handle_request\n    with map_httpcore_exceptions():\n         ~~~~~~~~~~~~~~~~~~~~~~~^^\n  File \"/opt/hostedtoolcache/Python/3.13.7/x64/lib/python3.13/contextlib.py\", line 162, in __exit__\n    self.gen.throw(value)\n    ~~~~~~~~~~~~~~^^^^^^^\n  File \"/opt/hostedtoolcache/Python/3.13.7/x64/lib/python3.13/site-packages/httpx/_transports/default.py\", line 118, in map_httpcore_exceptions\n    raise mapped_exc(message) from exc\n","steps":[{"name":"Make POST request to '/api/v1/users'","time":{"start":1756229240096,"stop":1756229240097,"duration":1},"status":"broken","statusMessage":"httpx.ConnectError: [Errno 111] Connection refused\n","statusTrace":"  File \"/opt/hostedtoolcache/Python/3.13.7/x64/lib/python3.13/site-packages/allure_commons/_allure.py\", line 202, in impl\n    return func(*a, **kw)\n  File \"/home/runner/work/api_autotests/api_autotests/clients/api_client.py\", line 19, in post\n    return self.client.post(url, json=json, data=data, files=files)\n           ~~~~~~~~~~~~~~~~^^^^^^^^^^^^^^^^^^^^^^^^^^^^^^^^^^^^^^^^\n  File \"/opt/hostedtoolcache/Python/3.13.7/x64/lib/python3.13/site-packages/httpx/_client.py\", line 1144, in post\n    return self.request(\n           ~~~~~~~~~~~~^\n        \"POST\",\n        ^^^^^^^\n    ...<11 lines>...\n        extensions=extensions,\n        ^^^^^^^^^^^^^^^^^^^^^^\n    )\n    ^\n  File \"/opt/hostedtoolcache/Python/3.13.7/x64/lib/python3.13/site-packages/httpx/_client.py\", line 825, in request\n    return self.send(request, auth=auth, follow_redirects=follow_redirects)\n           ~~~~~~~~~^^^^^^^^^^^^^^^^^^^^^^^^^^^^^^^^^^^^^^^^^^^^^^^^^^^^^^^\n  File \"/opt/hostedtoolcache/Python/3.13.7/x64/lib/python3.13/site-packages/httpx/_client.py\", line 914, in send\n    response = self._send_handling_auth(\n        request,\n    ...<2 lines>...\n        history=[],\n    )\n  File \"/opt/hostedtoolcache/Python/3.13.7/x64/lib/python3.13/site-packages/httpx/_client.py\", line 942, in _send_handling_auth\n    response = self._send_handling_redirects(\n        request,\n        follow_redirects=follow_redirects,\n        history=history,\n    )\n  File \"/opt/hostedtoolcache/Python/3.13.7/x64/lib/python3.13/site-packages/httpx/_client.py\", line 979, in _send_handling_redirects\n    response = self._send_single_request(request)\n  File \"/opt/hostedtoolcache/Python/3.13.7/x64/lib/python3.13/site-packages/httpx/_client.py\", line 1014, in _send_single_request\n    response = transport.handle_request(request)\n  File \"/opt/hostedtoolcache/Python/3.13.7/x64/lib/python3.13/site-packages/httpx/_transports/default.py\", line 249, in handle_request\n    with map_httpcore_exceptions():\n         ~~~~~~~~~~~~~~~~~~~~~~~^^\n  File \"/opt/hostedtoolcache/Python/3.13.7/x64/lib/python3.13/contextlib.py\", line 162, in __exit__\n    self.gen.throw(value)\n    ~~~~~~~~~~~~~~^^^^^^^\n  File \"/opt/hostedtoolcache/Python/3.13.7/x64/lib/python3.13/site-packages/httpx/_transports/default.py\", line 118, in map_httpcore_exceptions\n    raise mapped_exc(message) from exc\n","steps":[],"attachments":[{"uid":"b70b903eb25b1a42","name":"cURL command","source":"b70b903eb25b1a42.txt","type":"text/plain","size":450}],"parameters":[{"name":"url","value":"'/api/v1/users'"},{"name":"json","value":"{'email': 'vladilen_35@example.net', 'password': 'h!N!musD#3', 'lastName': 'Крюкова', 'firstName': 'Регина', 'middleName': 'Кузьминична'}"},{"name":"data","value":"None"},{"name":"files","value":"None"}],"stepsCount":0,"shouldDisplayMessage":true,"attachmentsCount":1,"hasContent":true,"attachmentStep":false}],"attachments":[],"parameters":[{"name":"request","value":"CreateUserRequestSchema(email='vladilen_35@example.net', password='h!N!musD#3', last_name='Крюкова', first_name='Регина', middle_name='Кузьминична')"}],"stepsCount":1,"shouldDisplayMessage":false,"attachmentsCount":1,"hasContent":true,"attachmentStep":false}],"attachments":[],"parameters":[],"stepsCount":2,"shouldDisplayMessage":false,"attachmentsCount":1,"hasContent":true,"attachmentStep":false}],"testStage":{"status":"broken","statusMessage":"httpx.ConnectError: [Errno 111] Connection refused","statusTrace":"@contextlib.contextmanager\n    def map_httpcore_exceptions() -> typing.Iterator[None]:\n        global HTTPCORE_EXC_MAP\n        if len(HTTPCORE_EXC_MAP) == 0:\n            HTTPCORE_EXC_MAP = _load_httpcore_exceptions()\n        try:\n>           yield\n\n/opt/hostedtoolcache/Python/3.13.7/x64/lib/python3.13/site-packages/httpx/_transports/default.py:101: \n_ _ _ _ _ _ _ _ _ _ _ _ _ _ _ _ _ _ _ _ _ _ _ _ _ _ _ _ _ _ _ _ _ _ _ _ _ _ _ _ \n/opt/hostedtoolcache/Python/3.13.7/x64/lib/python3.13/site-packages/httpx/_transports/default.py:250: in handle_request\n    resp = self._pool.handle_request(req)\n           ^^^^^^^^^^^^^^^^^^^^^^^^^^^^^^\n/opt/hostedtoolcache/Python/3.13.7/x64/lib/python3.13/site-packages/httpcore/_sync/connection_pool.py:256: in handle_request\n    raise exc from None\n/opt/hostedtoolcache/Python/3.13.7/x64/lib/python3.13/site-packages/httpcore/_sync/connection_pool.py:236: in handle_request\n    response = connection.handle_request(\n/opt/hostedtoolcache/Python/3.13.7/x64/lib/python3.13/site-packages/httpcore/_sync/connection.py:101: in handle_request\n    raise exc\n/opt/hostedtoolcache/Python/3.13.7/x64/lib/python3.13/site-packages/httpcore/_sync/connection.py:78: in handle_request\n    stream = self._connect(request)\n             ^^^^^^^^^^^^^^^^^^^^^^\n/opt/hostedtoolcache/Python/3.13.7/x64/lib/python3.13/site-packages/httpcore/_sync/connection.py:124: in _connect\n    stream = self._network_backend.connect_tcp(**kwargs)\n             ^^^^^^^^^^^^^^^^^^^^^^^^^^^^^^^^^^^^^^^^^^^\n/opt/hostedtoolcache/Python/3.13.7/x64/lib/python3.13/site-packages/httpcore/_backends/sync.py:207: in connect_tcp\n    with map_exceptions(exc_map):\n         ^^^^^^^^^^^^^^^^^^^^^^^\n/opt/hostedtoolcache/Python/3.13.7/x64/lib/python3.13/contextlib.py:162: in __exit__\n    self.gen.throw(value)\n_ _ _ _ _ _ _ _ _ _ _ _ _ _ _ _ _ _ _ _ _ _ _ _ _ _ _ _ _ _ _ _ _ _ _ _ _ _ _ _ \n\nmap = {<class 'TimeoutError'>: <class 'httpcore.ConnectTimeout'>, <class 'OSError'>: <class 'httpcore.ConnectError'>}\n\n    @contextlib.contextmanager\n    def map_exceptions(map: ExceptionMapping) -> typing.Iterator[None]:\n        try:\n            yield\n        except Exception as exc:  # noqa: PIE786\n            for from_exc, to_exc in map.items():\n                if isinstance(exc, from_exc):\n>                   raise to_exc(exc) from exc\nE                   httpcore.ConnectError: [Errno 111] Connection refused\n\n/opt/hostedtoolcache/Python/3.13.7/x64/lib/python3.13/site-packages/httpcore/_exceptions.py:14: ConnectError\n\nThe above exception was the direct cause of the following exception:\n\npublic_users_client = <clients.users.public_users_client.PublicUsersClient object at 0x7f34e58d1a90>\n\n    @pytest.fixture\n    def create_user(public_users_client: PublicUsersClient) -> UserData:\n        request = CreateUserRequestSchema()\n>       response = public_users_client.create_user(request)\n                   ^^^^^^^^^^^^^^^^^^^^^^^^^^^^^^^^^^^^^^^^\n\nfixtures/users.py:30: \n_ _ _ _ _ _ _ _ _ _ _ _ _ _ _ _ _ _ _ _ _ _ _ _ _ _ _ _ _ _ _ _ _ _ _ _ _ _ _ _ \nclients/users/public_users_client.py:17: in create_user\n    response = self.create_user_api(request)\n               ^^^^^^^^^^^^^^^^^^^^^^^^^^^^^\nclients/users/public_users_client.py:14: in create_user_api\n    return self.post(APIRoutes.USERS, json=request.model_dump(by_alias=True))\n           ^^^^^^^^^^^^^^^^^^^^^^^^^^^^^^^^^^^^^^^^^^^^^^^^^^^^^^^^^^^^^^^^^^\nclients/api_client.py:19: in post\n    return self.client.post(url, json=json, data=data, files=files)\n           ^^^^^^^^^^^^^^^^^^^^^^^^^^^^^^^^^^^^^^^^^^^^^^^^^^^^^^^^\n/opt/hostedtoolcache/Python/3.13.7/x64/lib/python3.13/site-packages/httpx/_client.py:1144: in post\n    return self.request(\n/opt/hostedtoolcache/Python/3.13.7/x64/lib/python3.13/site-packages/httpx/_client.py:825: in request\n    return self.send(request, auth=auth, follow_redirects=follow_redirects)\n           ^^^^^^^^^^^^^^^^^^^^^^^^^^^^^^^^^^^^^^^^^^^^^^^^^^^^^^^^^^^^^^^^\n/opt/hostedtoolcache/Python/3.13.7/x64/lib/python3.13/site-packages/httpx/_client.py:914: in send\n    response = self._send_handling_auth(\n/opt/hostedtoolcache/Python/3.13.7/x64/lib/python3.13/site-packages/httpx/_client.py:942: in _send_handling_auth\n    response = self._send_handling_redirects(\n/opt/hostedtoolcache/Python/3.13.7/x64/lib/python3.13/site-packages/httpx/_client.py:979: in _send_handling_redirects\n    response = self._send_single_request(request)\n               ^^^^^^^^^^^^^^^^^^^^^^^^^^^^^^^^^^\n/opt/hostedtoolcache/Python/3.13.7/x64/lib/python3.13/site-packages/httpx/_client.py:1014: in _send_single_request\n    response = transport.handle_request(request)\n               ^^^^^^^^^^^^^^^^^^^^^^^^^^^^^^^^^\n/opt/hostedtoolcache/Python/3.13.7/x64/lib/python3.13/site-packages/httpx/_transports/default.py:249: in handle_request\n    with map_httpcore_exceptions():\n         ^^^^^^^^^^^^^^^^^^^^^^^^^\n/opt/hostedtoolcache/Python/3.13.7/x64/lib/python3.13/contextlib.py:162: in __exit__\n    self.gen.throw(value)\n_ _ _ _ _ _ _ _ _ _ _ _ _ _ _ _ _ _ _ _ _ _ _ _ _ _ _ _ _ _ _ _ _ _ _ _ _ _ _ _ \n\n    @contextlib.contextmanager\n    def map_httpcore_exceptions() -> typing.Iterator[None]:\n        global HTTPCORE_EXC_MAP\n        if len(HTTPCORE_EXC_MAP) == 0:\n            HTTPCORE_EXC_MAP = _load_httpcore_exceptions()\n        try:\n            yield\n        except Exception as exc:\n            mapped_exc = None\n    \n            for from_exc, to_exc in HTTPCORE_EXC_MAP.items():\n                if not isinstance(exc, from_exc):\n                    continue\n                # We want to map to the most specific exception we can find.\n                # Eg if `exc` is an `httpcore.ReadTimeout`, we want to map to\n                # `httpx.ReadTimeout`, not just `httpx.TimeoutException`.\n                if mapped_exc is None or issubclass(to_exc, mapped_exc):\n                    mapped_exc = to_exc\n    \n            if mapped_exc is None:  # pragma: no cover\n                raise\n    \n            message = str(exc)\n>           raise mapped_exc(message) from exc\nE           httpx.ConnectError: [Errno 111] Connection refused\n\n/opt/hostedtoolcache/Python/3.13.7/x64/lib/python3.13/site-packages/httpx/_transports/default.py:118: ConnectError","steps":[],"attachments":[{"uid":"ecc08d05b9273297","name":"log","source":"ecc08d05b9273297.txt","type":"text/plain","size":94}],"parameters":[],"stepsCount":0,"shouldDisplayMessage":true,"attachmentsCount":1,"hasContent":true,"attachmentStep":false},"afterStages":[{"name":"save_allure_environment_file::0","time":{"start":1756229240636,"stop":1756229240637,"duration":1},"status":"passed","steps":[],"attachments":[],"parameters":[],"stepsCount":0,"shouldDisplayMessage":false,"attachmentsCount":0,"hasContent":false,"attachmentStep":false}],"labels":[{"name":"epic","value":"LMS service"},{"name":"parentSuite","value":"LMS service"},{"name":"suite","value":"Users"},{"name":"severity","value":"normal"},{"name":"subSuite","value":"Validate entity"},{"name":"story","value":"Validate entity"},{"name":"feature","value":"Users"},{"name":"tag","value":"errors"},{"name":"tag","value":"regression"},{"name":"tag","value":"users"},{"name":"tag","value":"delete"},{"name":"host","value":"pkrvmqc4gcfdwos"},{"name":"thread","value":"2409-MainThread"},{"name":"framework","value":"pytest"},{"name":"language","value":"cpython3"},{"name":"package","value":"tests.test_users.test_delete_user"},{"name":"resultFormat","value":"allure2"}],"parameters":[],"links":[],"hidden":false,"retry":false,"extra":{"severity":"normal","retries":[],"categories":[{"name":"Test defects","matchedStatuses":[],"flaky":false}],"history":{"statistic":{"failed":0,"broken":5,"skipped":0,"passed":0,"unknown":0,"total":5},"items":[{"uid":"778037f36bb00326","reportUrl":"https://bogdanshcherban8.github.io/api_autotests/4/#testresult/778037f36bb00326","status":"broken","statusDetails":"httpx.ConnectError: [Errno 111] Connection refused","time":{"start":1756228916599,"stop":1756228916599,"duration":0}},{"uid":"143f4d3cd30c17e","reportUrl":"https://bogdanshcherban8.github.io/api_autotests/3/#testresult/143f4d3cd30c17e","status":"broken","statusDetails":"httpx.ConnectError: [Errno -3] Temporary failure in name resolution","time":{"start":1756228637080,"stop":1756228637080,"duration":0}},{"uid":"4a4b27816068da7","reportUrl":"https://bogdanshcherban8.github.io/api_autotests/2/#testresult/4a4b27816068da7","status":"broken","statusDetails":"httpx.ConnectError: [Errno -3] Temporary failure in name resolution","time":{"start":1756228281957,"stop":1756228281957,"duration":0}},{"uid":"93fad57f6469061c","reportUrl":"https://bogdanshcherban8.github.io/api_autotests/1/#testresult/93fad57f6469061c","status":"broken","statusDetails":"httpx.ConnectError: [Errno 111] Connection refused","time":{"start":1756227882976,"stop":1756227882976,"duration":0}}]},"tags":["regression","delete","errors","users"]},"source":"b7dcc3a466b916fe.json","parameterValues":[]}