{"uid":"e9b2cad33e58ba45","name":"User creates course with incorrect data","fullName":"tests.test_courses.test_create_course.TestCreateCourse#test_create_course_with_incorrect_data","historyId":"304a50a66d6a0a4e676d928213fc52c1","time":{"start":1756228906588,"stop":1756228906588,"duration":0},"status":"broken","statusMessage":"httpx.ConnectError: [Errno 111] Connection refused","statusTrace":"@contextlib.contextmanager\n    def map_httpcore_exceptions() -> typing.Iterator[None]:\n        global HTTPCORE_EXC_MAP\n        if len(HTTPCORE_EXC_MAP) == 0:\n            HTTPCORE_EXC_MAP = _load_httpcore_exceptions()\n        try:\n>           yield\n\n/opt/hostedtoolcache/Python/3.13.7/x64/lib/python3.13/site-packages/httpx/_transports/default.py:101: \n_ _ _ _ _ _ _ _ _ _ _ _ _ _ _ _ _ _ _ _ _ _ _ _ _ _ _ _ _ _ _ _ _ _ _ _ _ _ _ _ \n/opt/hostedtoolcache/Python/3.13.7/x64/lib/python3.13/site-packages/httpx/_transports/default.py:250: in handle_request\n    resp = self._pool.handle_request(req)\n           ^^^^^^^^^^^^^^^^^^^^^^^^^^^^^^\n/opt/hostedtoolcache/Python/3.13.7/x64/lib/python3.13/site-packages/httpcore/_sync/connection_pool.py:256: in handle_request\n    raise exc from None\n/opt/hostedtoolcache/Python/3.13.7/x64/lib/python3.13/site-packages/httpcore/_sync/connection_pool.py:236: in handle_request\n    response = connection.handle_request(\n/opt/hostedtoolcache/Python/3.13.7/x64/lib/python3.13/site-packages/httpcore/_sync/connection.py:101: in handle_request\n    raise exc\n/opt/hostedtoolcache/Python/3.13.7/x64/lib/python3.13/site-packages/httpcore/_sync/connection.py:78: in handle_request\n    stream = self._connect(request)\n             ^^^^^^^^^^^^^^^^^^^^^^\n/opt/hostedtoolcache/Python/3.13.7/x64/lib/python3.13/site-packages/httpcore/_sync/connection.py:124: in _connect\n    stream = self._network_backend.connect_tcp(**kwargs)\n             ^^^^^^^^^^^^^^^^^^^^^^^^^^^^^^^^^^^^^^^^^^^\n/opt/hostedtoolcache/Python/3.13.7/x64/lib/python3.13/site-packages/httpcore/_backends/sync.py:207: in connect_tcp\n    with map_exceptions(exc_map):\n         ^^^^^^^^^^^^^^^^^^^^^^^\n/opt/hostedtoolcache/Python/3.13.7/x64/lib/python3.13/contextlib.py:162: in __exit__\n    self.gen.throw(value)\n_ _ _ _ _ _ _ _ _ _ _ _ _ _ _ _ _ _ _ _ _ _ _ _ _ _ _ _ _ _ _ _ _ _ _ _ _ _ _ _ \n\nmap = {<class 'TimeoutError'>: <class 'httpcore.ConnectTimeout'>, <class 'OSError'>: <class 'httpcore.ConnectError'>}\n\n    @contextlib.contextmanager\n    def map_exceptions(map: ExceptionMapping) -> typing.Iterator[None]:\n        try:\n            yield\n        except Exception as exc:  # noqa: PIE786\n            for from_exc, to_exc in map.items():\n                if isinstance(exc, from_exc):\n>                   raise to_exc(exc) from exc\nE                   httpcore.ConnectError: [Errno 111] Connection refused\n\n/opt/hostedtoolcache/Python/3.13.7/x64/lib/python3.13/site-packages/httpcore/_exceptions.py:14: ConnectError\n\nThe above exception was the direct cause of the following exception:\n\npublic_users_client = <clients.users.public_users_client.PublicUsersClient object at 0x7fbd30a9a350>\n\n    @pytest.fixture\n    def create_user(public_users_client: PublicUsersClient) -> UserData:\n        request = CreateUserRequestSchema()\n>       response = public_users_client.create_user(request)\n                   ^^^^^^^^^^^^^^^^^^^^^^^^^^^^^^^^^^^^^^^^\n\nfixtures/users.py:30: \n_ _ _ _ _ _ _ _ _ _ _ _ _ _ _ _ _ _ _ _ _ _ _ _ _ _ _ _ _ _ _ _ _ _ _ _ _ _ _ _ \nclients/users/public_users_client.py:17: in create_user\n    response = self.create_user_api(request)\n               ^^^^^^^^^^^^^^^^^^^^^^^^^^^^^\nclients/users/public_users_client.py:14: in create_user_api\n    return self.post(APIRoutes.USERS, json=request.model_dump(by_alias=True))\n           ^^^^^^^^^^^^^^^^^^^^^^^^^^^^^^^^^^^^^^^^^^^^^^^^^^^^^^^^^^^^^^^^^^\nclients/api_client.py:19: in post\n    return self.client.post(url, json=json, data=data, files=files)\n           ^^^^^^^^^^^^^^^^^^^^^^^^^^^^^^^^^^^^^^^^^^^^^^^^^^^^^^^^\n/opt/hostedtoolcache/Python/3.13.7/x64/lib/python3.13/site-packages/httpx/_client.py:1144: in post\n    return self.request(\n/opt/hostedtoolcache/Python/3.13.7/x64/lib/python3.13/site-packages/httpx/_client.py:825: in request\n    return self.send(request, auth=auth, follow_redirects=follow_redirects)\n           ^^^^^^^^^^^^^^^^^^^^^^^^^^^^^^^^^^^^^^^^^^^^^^^^^^^^^^^^^^^^^^^^\n/opt/hostedtoolcache/Python/3.13.7/x64/lib/python3.13/site-packages/httpx/_client.py:914: in send\n    response = self._send_handling_auth(\n/opt/hostedtoolcache/Python/3.13.7/x64/lib/python3.13/site-packages/httpx/_client.py:942: in _send_handling_auth\n    response = self._send_handling_redirects(\n/opt/hostedtoolcache/Python/3.13.7/x64/lib/python3.13/site-packages/httpx/_client.py:979: in _send_handling_redirects\n    response = self._send_single_request(request)\n               ^^^^^^^^^^^^^^^^^^^^^^^^^^^^^^^^^^\n/opt/hostedtoolcache/Python/3.13.7/x64/lib/python3.13/site-packages/httpx/_client.py:1014: in _send_single_request\n    response = transport.handle_request(request)\n               ^^^^^^^^^^^^^^^^^^^^^^^^^^^^^^^^^\n/opt/hostedtoolcache/Python/3.13.7/x64/lib/python3.13/site-packages/httpx/_transports/default.py:249: in handle_request\n    with map_httpcore_exceptions():\n         ^^^^^^^^^^^^^^^^^^^^^^^^^\n/opt/hostedtoolcache/Python/3.13.7/x64/lib/python3.13/contextlib.py:162: in __exit__\n    self.gen.throw(value)\n_ _ _ _ _ _ _ _ _ _ _ _ _ _ _ _ _ _ _ _ _ _ _ _ _ _ _ _ _ _ _ _ _ _ _ _ _ _ _ _ \n\n    @contextlib.contextmanager\n    def map_httpcore_exceptions() -> typing.Iterator[None]:\n        global HTTPCORE_EXC_MAP\n        if len(HTTPCORE_EXC_MAP) == 0:\n            HTTPCORE_EXC_MAP = _load_httpcore_exceptions()\n        try:\n            yield\n        except Exception as exc:\n            mapped_exc = None\n    \n            for from_exc, to_exc in HTTPCORE_EXC_MAP.items():\n                if not isinstance(exc, from_exc):\n                    continue\n                # We want to map to the most specific exception we can find.\n                # Eg if `exc` is an `httpcore.ReadTimeout`, we want to map to\n                # `httpx.ReadTimeout`, not just `httpx.TimeoutException`.\n                if mapped_exc is None or issubclass(to_exc, mapped_exc):\n                    mapped_exc = to_exc\n    \n            if mapped_exc is None:  # pragma: no cover\n                raise\n    \n            message = str(exc)\n>           raise mapped_exc(message) from exc\nE           httpx.ConnectError: [Errno 111] Connection refused\n\n/opt/hostedtoolcache/Python/3.13.7/x64/lib/python3.13/site-packages/httpx/_transports/default.py:118: ConnectError","flaky":false,"newFailed":false,"newBroken":false,"newPassed":false,"retriesCount":0,"retriesStatusChange":false,"beforeStages":[{"name":"_session_faker","time":{"start":1756228906326,"stop":1756228906382,"duration":56},"status":"passed","steps":[],"attachments":[],"parameters":[],"stepsCount":0,"shouldDisplayMessage":false,"attachmentsCount":0,"hasContent":false,"attachmentStep":false},{"name":"save_allure_environment_file","time":{"start":1756228906382,"stop":1756228906382,"duration":0},"status":"passed","steps":[],"attachments":[],"parameters":[],"stepsCount":0,"shouldDisplayMessage":false,"attachmentsCount":0,"hasContent":false,"attachmentStep":false},{"name":"public_users_client","time":{"start":1756228906589,"stop":1756228906611,"duration":22},"status":"passed","steps":[],"attachments":[],"parameters":[],"stepsCount":0,"shouldDisplayMessage":false,"attachmentsCount":0,"hasContent":false,"attachmentStep":false},{"name":"create_user","time":{"start":1756228906611,"stop":1756228906616,"duration":5},"status":"broken","statusMessage":"httpx.ConnectError: [Errno 111] Connection refused\n","statusTrace":"  File \"/opt/hostedtoolcache/Python/3.13.7/x64/lib/python3.13/site-packages/pluggy/_callers.py\", line 38, in run_old_style_hookwrapper\n    res = yield\n          ^^^^^\n  File \"/opt/hostedtoolcache/Python/3.13.7/x64/lib/python3.13/site-packages/pluggy/_callers.py\", line 139, in _multicall\n    teardown.throw(exception)\n    ~~~~~~~~~~~~~~^^^^^^^^^^^\n  File \"/opt/hostedtoolcache/Python/3.13.7/x64/lib/python3.13/site-packages/pluggy/_callers.py\", line 53, in run_old_style_hookwrapper\n    return result.get_result()\n           ~~~~~~~~~~~~~~~~~^^\n  File \"/opt/hostedtoolcache/Python/3.13.7/x64/lib/python3.13/site-packages/pluggy/_result.py\", line 103, in get_result\n    raise exc.with_traceback(tb)\n  File \"/opt/hostedtoolcache/Python/3.13.7/x64/lib/python3.13/site-packages/pluggy/_callers.py\", line 38, in run_old_style_hookwrapper\n    res = yield\n          ^^^^^\n  File \"/opt/hostedtoolcache/Python/3.13.7/x64/lib/python3.13/site-packages/pluggy/_callers.py\", line 139, in _multicall\n    teardown.throw(exception)\n    ~~~~~~~~~~~~~~^^^^^^^^^^^\n  File \"/opt/hostedtoolcache/Python/3.13.7/x64/lib/python3.13/site-packages/_pytest/setuponly.py\", line 36, in pytest_fixture_setup\n    return (yield)\n            ^^^^^\n  File \"/opt/hostedtoolcache/Python/3.13.7/x64/lib/python3.13/site-packages/pluggy/_callers.py\", line 121, in _multicall\n    res = hook_impl.function(*args)\n  File \"/opt/hostedtoolcache/Python/3.13.7/x64/lib/python3.13/site-packages/_pytest/fixtures.py\", line 1195, in pytest_fixture_setup\n    result = call_fixture_func(fixturefunc, request, kwargs)\n  File \"/opt/hostedtoolcache/Python/3.13.7/x64/lib/python3.13/site-packages/_pytest/fixtures.py\", line 929, in call_fixture_func\n    fixture_result = fixturefunc(**kwargs)\n  File \"/home/runner/work/api_autotests/api_autotests/fixtures/users.py\", line 30, in create_user\n    response = public_users_client.create_user(request)\n  File \"/home/runner/work/api_autotests/api_autotests/clients/users/public_users_client.py\", line 17, in create_user\n    response = self.create_user_api(request)\n  File \"/opt/hostedtoolcache/Python/3.13.7/x64/lib/python3.13/site-packages/allure_commons/_allure.py\", line 202, in impl\n    return func(*a, **kw)\n  File \"/home/runner/work/api_autotests/api_autotests/clients/users/public_users_client.py\", line 14, in create_user_api\n    return self.post(APIRoutes.USERS, json=request.model_dump(by_alias=True))\n           ~~~~~~~~~^^^^^^^^^^^^^^^^^^^^^^^^^^^^^^^^^^^^^^^^^^^^^^^^^^^^^^^^^\n  File \"/opt/hostedtoolcache/Python/3.13.7/x64/lib/python3.13/site-packages/allure_commons/_allure.py\", line 202, in impl\n    return func(*a, **kw)\n  File \"/home/runner/work/api_autotests/api_autotests/clients/api_client.py\", line 19, in post\n    return self.client.post(url, json=json, data=data, files=files)\n           ~~~~~~~~~~~~~~~~^^^^^^^^^^^^^^^^^^^^^^^^^^^^^^^^^^^^^^^^\n  File \"/opt/hostedtoolcache/Python/3.13.7/x64/lib/python3.13/site-packages/httpx/_client.py\", line 1144, in post\n    return self.request(\n           ~~~~~~~~~~~~^\n        \"POST\",\n        ^^^^^^^\n    ...<11 lines>...\n        extensions=extensions,\n        ^^^^^^^^^^^^^^^^^^^^^^\n    )\n    ^\n  File \"/opt/hostedtoolcache/Python/3.13.7/x64/lib/python3.13/site-packages/httpx/_client.py\", line 825, in request\n    return self.send(request, auth=auth, follow_redirects=follow_redirects)\n           ~~~~~~~~~^^^^^^^^^^^^^^^^^^^^^^^^^^^^^^^^^^^^^^^^^^^^^^^^^^^^^^^\n  File \"/opt/hostedtoolcache/Python/3.13.7/x64/lib/python3.13/site-packages/httpx/_client.py\", line 914, in send\n    response = self._send_handling_auth(\n        request,\n    ...<2 lines>...\n        history=[],\n    )\n  File \"/opt/hostedtoolcache/Python/3.13.7/x64/lib/python3.13/site-packages/httpx/_client.py\", line 942, in _send_handling_auth\n    response = self._send_handling_redirects(\n        request,\n        follow_redirects=follow_redirects,\n        history=history,\n    )\n  File \"/opt/hostedtoolcache/Python/3.13.7/x64/lib/python3.13/site-packages/httpx/_client.py\", line 979, in _send_handling_redirects\n    response = self._send_single_request(request)\n  File \"/opt/hostedtoolcache/Python/3.13.7/x64/lib/python3.13/site-packages/httpx/_client.py\", line 1014, in _send_single_request\n    response = transport.handle_request(request)\n  File \"/opt/hostedtoolcache/Python/3.13.7/x64/lib/python3.13/site-packages/httpx/_transports/default.py\", line 249, in handle_request\n    with map_httpcore_exceptions():\n         ~~~~~~~~~~~~~~~~~~~~~~~^^\n  File \"/opt/hostedtoolcache/Python/3.13.7/x64/lib/python3.13/contextlib.py\", line 162, in __exit__\n    self.gen.throw(value)\n    ~~~~~~~~~~~~~~^^^^^^^\n  File \"/opt/hostedtoolcache/Python/3.13.7/x64/lib/python3.13/site-packages/httpx/_transports/default.py\", line 118, in map_httpcore_exceptions\n    raise mapped_exc(message) from exc\n","steps":[{"name":"Create user","time":{"start":1756228906611,"stop":1756228906614,"duration":3},"status":"broken","statusMessage":"httpx.ConnectError: [Errno 111] Connection refused\n","statusTrace":"  File \"/opt/hostedtoolcache/Python/3.13.7/x64/lib/python3.13/site-packages/allure_commons/_allure.py\", line 202, in impl\n    return func(*a, **kw)\n  File \"/home/runner/work/api_autotests/api_autotests/clients/users/public_users_client.py\", line 14, in create_user_api\n    return self.post(APIRoutes.USERS, json=request.model_dump(by_alias=True))\n           ~~~~~~~~~^^^^^^^^^^^^^^^^^^^^^^^^^^^^^^^^^^^^^^^^^^^^^^^^^^^^^^^^^\n  File \"/opt/hostedtoolcache/Python/3.13.7/x64/lib/python3.13/site-packages/allure_commons/_allure.py\", line 202, in impl\n    return func(*a, **kw)\n  File \"/home/runner/work/api_autotests/api_autotests/clients/api_client.py\", line 19, in post\n    return self.client.post(url, json=json, data=data, files=files)\n           ~~~~~~~~~~~~~~~~^^^^^^^^^^^^^^^^^^^^^^^^^^^^^^^^^^^^^^^^\n  File \"/opt/hostedtoolcache/Python/3.13.7/x64/lib/python3.13/site-packages/httpx/_client.py\", line 1144, in post\n    return self.request(\n           ~~~~~~~~~~~~^\n        \"POST\",\n        ^^^^^^^\n    ...<11 lines>...\n        extensions=extensions,\n        ^^^^^^^^^^^^^^^^^^^^^^\n    )\n    ^\n  File \"/opt/hostedtoolcache/Python/3.13.7/x64/lib/python3.13/site-packages/httpx/_client.py\", line 825, in request\n    return self.send(request, auth=auth, follow_redirects=follow_redirects)\n           ~~~~~~~~~^^^^^^^^^^^^^^^^^^^^^^^^^^^^^^^^^^^^^^^^^^^^^^^^^^^^^^^\n  File \"/opt/hostedtoolcache/Python/3.13.7/x64/lib/python3.13/site-packages/httpx/_client.py\", line 914, in send\n    response = self._send_handling_auth(\n        request,\n    ...<2 lines>...\n        history=[],\n    )\n  File \"/opt/hostedtoolcache/Python/3.13.7/x64/lib/python3.13/site-packages/httpx/_client.py\", line 942, in _send_handling_auth\n    response = self._send_handling_redirects(\n        request,\n        follow_redirects=follow_redirects,\n        history=history,\n    )\n  File \"/opt/hostedtoolcache/Python/3.13.7/x64/lib/python3.13/site-packages/httpx/_client.py\", line 979, in _send_handling_redirects\n    response = self._send_single_request(request)\n  File \"/opt/hostedtoolcache/Python/3.13.7/x64/lib/python3.13/site-packages/httpx/_client.py\", line 1014, in _send_single_request\n    response = transport.handle_request(request)\n  File \"/opt/hostedtoolcache/Python/3.13.7/x64/lib/python3.13/site-packages/httpx/_transports/default.py\", line 249, in handle_request\n    with map_httpcore_exceptions():\n         ~~~~~~~~~~~~~~~~~~~~~~~^^\n  File \"/opt/hostedtoolcache/Python/3.13.7/x64/lib/python3.13/contextlib.py\", line 162, in __exit__\n    self.gen.throw(value)\n    ~~~~~~~~~~~~~~^^^^^^^\n  File \"/opt/hostedtoolcache/Python/3.13.7/x64/lib/python3.13/site-packages/httpx/_transports/default.py\", line 118, in map_httpcore_exceptions\n    raise mapped_exc(message) from exc\n","steps":[{"name":"Make POST request to '/api/v1/users'","time":{"start":1756228906612,"stop":1756228906613,"duration":1},"status":"broken","statusMessage":"httpx.ConnectError: [Errno 111] Connection refused\n","statusTrace":"  File \"/opt/hostedtoolcache/Python/3.13.7/x64/lib/python3.13/site-packages/allure_commons/_allure.py\", line 202, in impl\n    return func(*a, **kw)\n  File \"/home/runner/work/api_autotests/api_autotests/clients/api_client.py\", line 19, in post\n    return self.client.post(url, json=json, data=data, files=files)\n           ~~~~~~~~~~~~~~~~^^^^^^^^^^^^^^^^^^^^^^^^^^^^^^^^^^^^^^^^\n  File \"/opt/hostedtoolcache/Python/3.13.7/x64/lib/python3.13/site-packages/httpx/_client.py\", line 1144, in post\n    return self.request(\n           ~~~~~~~~~~~~^\n        \"POST\",\n        ^^^^^^^\n    ...<11 lines>...\n        extensions=extensions,\n        ^^^^^^^^^^^^^^^^^^^^^^\n    )\n    ^\n  File \"/opt/hostedtoolcache/Python/3.13.7/x64/lib/python3.13/site-packages/httpx/_client.py\", line 825, in request\n    return self.send(request, auth=auth, follow_redirects=follow_redirects)\n           ~~~~~~~~~^^^^^^^^^^^^^^^^^^^^^^^^^^^^^^^^^^^^^^^^^^^^^^^^^^^^^^^\n  File \"/opt/hostedtoolcache/Python/3.13.7/x64/lib/python3.13/site-packages/httpx/_client.py\", line 914, in send\n    response = self._send_handling_auth(\n        request,\n    ...<2 lines>...\n        history=[],\n    )\n  File \"/opt/hostedtoolcache/Python/3.13.7/x64/lib/python3.13/site-packages/httpx/_client.py\", line 942, in _send_handling_auth\n    response = self._send_handling_redirects(\n        request,\n        follow_redirects=follow_redirects,\n        history=history,\n    )\n  File \"/opt/hostedtoolcache/Python/3.13.7/x64/lib/python3.13/site-packages/httpx/_client.py\", line 979, in _send_handling_redirects\n    response = self._send_single_request(request)\n  File \"/opt/hostedtoolcache/Python/3.13.7/x64/lib/python3.13/site-packages/httpx/_client.py\", line 1014, in _send_single_request\n    response = transport.handle_request(request)\n  File \"/opt/hostedtoolcache/Python/3.13.7/x64/lib/python3.13/site-packages/httpx/_transports/default.py\", line 249, in handle_request\n    with map_httpcore_exceptions():\n         ~~~~~~~~~~~~~~~~~~~~~~~^^\n  File \"/opt/hostedtoolcache/Python/3.13.7/x64/lib/python3.13/contextlib.py\", line 162, in __exit__\n    self.gen.throw(value)\n    ~~~~~~~~~~~~~~^^^^^^^\n  File \"/opt/hostedtoolcache/Python/3.13.7/x64/lib/python3.13/site-packages/httpx/_transports/default.py\", line 118, in map_httpcore_exceptions\n    raise mapped_exc(message) from exc\n","steps":[],"attachments":[{"uid":"8eb637f3a69c3495","name":"cURL command","source":"8eb637f3a69c3495.txt","type":"text/plain","size":441}],"parameters":[{"name":"url","value":"'/api/v1/users'"},{"name":"json","value":"{'email': 'artem_2017@example.org', 'password': '(21YfJ(L!H', 'lastName': 'Дьячков', 'firstName': 'Эраст', 'middleName': 'Гурьевич'}"},{"name":"data","value":"None"},{"name":"files","value":"None"}],"stepsCount":0,"shouldDisplayMessage":true,"attachmentsCount":1,"hasContent":true,"attachmentStep":false}],"attachments":[],"parameters":[{"name":"request","value":"CreateUserRequestSchema(email='artem_2017@example.org', password='(21YfJ(L!H', last_name='Дьячков', first_name='Эраст', middle_name='Гурьевич')"}],"stepsCount":1,"shouldDisplayMessage":false,"attachmentsCount":1,"hasContent":true,"attachmentStep":false}],"attachments":[],"parameters":[],"stepsCount":2,"shouldDisplayMessage":false,"attachmentsCount":1,"hasContent":true,"attachmentStep":false}],"testStage":{"status":"broken","statusMessage":"httpx.ConnectError: [Errno 111] Connection refused","statusTrace":"@contextlib.contextmanager\n    def map_httpcore_exceptions() -> typing.Iterator[None]:\n        global HTTPCORE_EXC_MAP\n        if len(HTTPCORE_EXC_MAP) == 0:\n            HTTPCORE_EXC_MAP = _load_httpcore_exceptions()\n        try:\n>           yield\n\n/opt/hostedtoolcache/Python/3.13.7/x64/lib/python3.13/site-packages/httpx/_transports/default.py:101: \n_ _ _ _ _ _ _ _ _ _ _ _ _ _ _ _ _ _ _ _ _ _ _ _ _ _ _ _ _ _ _ _ _ _ _ _ _ _ _ _ \n/opt/hostedtoolcache/Python/3.13.7/x64/lib/python3.13/site-packages/httpx/_transports/default.py:250: in handle_request\n    resp = self._pool.handle_request(req)\n           ^^^^^^^^^^^^^^^^^^^^^^^^^^^^^^\n/opt/hostedtoolcache/Python/3.13.7/x64/lib/python3.13/site-packages/httpcore/_sync/connection_pool.py:256: in handle_request\n    raise exc from None\n/opt/hostedtoolcache/Python/3.13.7/x64/lib/python3.13/site-packages/httpcore/_sync/connection_pool.py:236: in handle_request\n    response = connection.handle_request(\n/opt/hostedtoolcache/Python/3.13.7/x64/lib/python3.13/site-packages/httpcore/_sync/connection.py:101: in handle_request\n    raise exc\n/opt/hostedtoolcache/Python/3.13.7/x64/lib/python3.13/site-packages/httpcore/_sync/connection.py:78: in handle_request\n    stream = self._connect(request)\n             ^^^^^^^^^^^^^^^^^^^^^^\n/opt/hostedtoolcache/Python/3.13.7/x64/lib/python3.13/site-packages/httpcore/_sync/connection.py:124: in _connect\n    stream = self._network_backend.connect_tcp(**kwargs)\n             ^^^^^^^^^^^^^^^^^^^^^^^^^^^^^^^^^^^^^^^^^^^\n/opt/hostedtoolcache/Python/3.13.7/x64/lib/python3.13/site-packages/httpcore/_backends/sync.py:207: in connect_tcp\n    with map_exceptions(exc_map):\n         ^^^^^^^^^^^^^^^^^^^^^^^\n/opt/hostedtoolcache/Python/3.13.7/x64/lib/python3.13/contextlib.py:162: in __exit__\n    self.gen.throw(value)\n_ _ _ _ _ _ _ _ _ _ _ _ _ _ _ _ _ _ _ _ _ _ _ _ _ _ _ _ _ _ _ _ _ _ _ _ _ _ _ _ \n\nmap = {<class 'TimeoutError'>: <class 'httpcore.ConnectTimeout'>, <class 'OSError'>: <class 'httpcore.ConnectError'>}\n\n    @contextlib.contextmanager\n    def map_exceptions(map: ExceptionMapping) -> typing.Iterator[None]:\n        try:\n            yield\n        except Exception as exc:  # noqa: PIE786\n            for from_exc, to_exc in map.items():\n                if isinstance(exc, from_exc):\n>                   raise to_exc(exc) from exc\nE                   httpcore.ConnectError: [Errno 111] Connection refused\n\n/opt/hostedtoolcache/Python/3.13.7/x64/lib/python3.13/site-packages/httpcore/_exceptions.py:14: ConnectError\n\nThe above exception was the direct cause of the following exception:\n\npublic_users_client = <clients.users.public_users_client.PublicUsersClient object at 0x7fbd30a9a350>\n\n    @pytest.fixture\n    def create_user(public_users_client: PublicUsersClient) -> UserData:\n        request = CreateUserRequestSchema()\n>       response = public_users_client.create_user(request)\n                   ^^^^^^^^^^^^^^^^^^^^^^^^^^^^^^^^^^^^^^^^\n\nfixtures/users.py:30: \n_ _ _ _ _ _ _ _ _ _ _ _ _ _ _ _ _ _ _ _ _ _ _ _ _ _ _ _ _ _ _ _ _ _ _ _ _ _ _ _ \nclients/users/public_users_client.py:17: in create_user\n    response = self.create_user_api(request)\n               ^^^^^^^^^^^^^^^^^^^^^^^^^^^^^\nclients/users/public_users_client.py:14: in create_user_api\n    return self.post(APIRoutes.USERS, json=request.model_dump(by_alias=True))\n           ^^^^^^^^^^^^^^^^^^^^^^^^^^^^^^^^^^^^^^^^^^^^^^^^^^^^^^^^^^^^^^^^^^\nclients/api_client.py:19: in post\n    return self.client.post(url, json=json, data=data, files=files)\n           ^^^^^^^^^^^^^^^^^^^^^^^^^^^^^^^^^^^^^^^^^^^^^^^^^^^^^^^^\n/opt/hostedtoolcache/Python/3.13.7/x64/lib/python3.13/site-packages/httpx/_client.py:1144: in post\n    return self.request(\n/opt/hostedtoolcache/Python/3.13.7/x64/lib/python3.13/site-packages/httpx/_client.py:825: in request\n    return self.send(request, auth=auth, follow_redirects=follow_redirects)\n           ^^^^^^^^^^^^^^^^^^^^^^^^^^^^^^^^^^^^^^^^^^^^^^^^^^^^^^^^^^^^^^^^\n/opt/hostedtoolcache/Python/3.13.7/x64/lib/python3.13/site-packages/httpx/_client.py:914: in send\n    response = self._send_handling_auth(\n/opt/hostedtoolcache/Python/3.13.7/x64/lib/python3.13/site-packages/httpx/_client.py:942: in _send_handling_auth\n    response = self._send_handling_redirects(\n/opt/hostedtoolcache/Python/3.13.7/x64/lib/python3.13/site-packages/httpx/_client.py:979: in _send_handling_redirects\n    response = self._send_single_request(request)\n               ^^^^^^^^^^^^^^^^^^^^^^^^^^^^^^^^^^\n/opt/hostedtoolcache/Python/3.13.7/x64/lib/python3.13/site-packages/httpx/_client.py:1014: in _send_single_request\n    response = transport.handle_request(request)\n               ^^^^^^^^^^^^^^^^^^^^^^^^^^^^^^^^^\n/opt/hostedtoolcache/Python/3.13.7/x64/lib/python3.13/site-packages/httpx/_transports/default.py:249: in handle_request\n    with map_httpcore_exceptions():\n         ^^^^^^^^^^^^^^^^^^^^^^^^^\n/opt/hostedtoolcache/Python/3.13.7/x64/lib/python3.13/contextlib.py:162: in __exit__\n    self.gen.throw(value)\n_ _ _ _ _ _ _ _ _ _ _ _ _ _ _ _ _ _ _ _ _ _ _ _ _ _ _ _ _ _ _ _ _ _ _ _ _ _ _ _ \n\n    @contextlib.contextmanager\n    def map_httpcore_exceptions() -> typing.Iterator[None]:\n        global HTTPCORE_EXC_MAP\n        if len(HTTPCORE_EXC_MAP) == 0:\n            HTTPCORE_EXC_MAP = _load_httpcore_exceptions()\n        try:\n            yield\n        except Exception as exc:\n            mapped_exc = None\n    \n            for from_exc, to_exc in HTTPCORE_EXC_MAP.items():\n                if not isinstance(exc, from_exc):\n                    continue\n                # We want to map to the most specific exception we can find.\n                # Eg if `exc` is an `httpcore.ReadTimeout`, we want to map to\n                # `httpx.ReadTimeout`, not just `httpx.TimeoutException`.\n                if mapped_exc is None or issubclass(to_exc, mapped_exc):\n                    mapped_exc = to_exc\n    \n            if mapped_exc is None:  # pragma: no cover\n                raise\n    \n            message = str(exc)\n>           raise mapped_exc(message) from exc\nE           httpx.ConnectError: [Errno 111] Connection refused\n\n/opt/hostedtoolcache/Python/3.13.7/x64/lib/python3.13/site-packages/httpx/_transports/default.py:118: ConnectError","steps":[],"attachments":[{"uid":"f26f9efb809beaaa","name":"log","source":"f26f9efb809beaaa.txt","type":"text/plain","size":94}],"parameters":[],"stepsCount":0,"shouldDisplayMessage":true,"attachmentsCount":1,"hasContent":true,"attachmentStep":false},"afterStages":[{"name":"save_allure_environment_file::0","time":{"start":1756228917207,"stop":1756228917207,"duration":0},"status":"passed","steps":[],"attachments":[],"parameters":[],"stepsCount":0,"shouldDisplayMessage":false,"attachmentsCount":0,"hasContent":false,"attachmentStep":false}],"labels":[{"name":"story","value":"Validate entity"},{"name":"suite","value":"Courses"},{"name":"severity","value":"normal"},{"name":"epic","value":"LMS service"},{"name":"subSuite","value":"Validate entity"},{"name":"feature","value":"Courses"},{"name":"parentSuite","value":"LMS service"},{"name":"tag","value":"errors"},{"name":"tag","value":"regression"},{"name":"tag","value":"courses"},{"name":"tag","value":"create"},{"name":"host","value":"pkrvmqc4gcfdwos"},{"name":"thread","value":"2430-MainThread"},{"name":"framework","value":"pytest"},{"name":"language","value":"cpython3"},{"name":"package","value":"tests.test_courses.test_create_course"},{"name":"resultFormat","value":"allure2"}],"parameters":[{"name":"context","value":"{'min_length': 1}"},{"name":"field","value":"'estimated_time'"},{"name":"incorrect_value","value":"''"},{"name":"location","value":"'estimatedTime'"},{"name":"message","value":"'String should have at least 1 character'"},{"name":"type_text","value":"'string_too_short'"}],"links":[],"hidden":false,"retry":false,"extra":{"severity":"normal","retries":[],"categories":[{"name":"Test defects","matchedStatuses":[],"flaky":false}],"history":{"statistic":{"failed":0,"broken":4,"skipped":0,"passed":0,"unknown":0,"total":4},"items":[{"uid":"2613f1e35c53708a","reportUrl":"https://bogdanshcherban8.github.io/api_autotests/3/#testresult/2613f1e35c53708a","status":"broken","statusDetails":"httpx.ConnectError: [Errno -3] Temporary failure in name resolution","time":{"start":1756228627148,"stop":1756228627148,"duration":0}},{"uid":"680bf0ebee850f11","reportUrl":"https://bogdanshcherban8.github.io/api_autotests/2/#testresult/680bf0ebee850f11","status":"broken","statusDetails":"httpx.ConnectError: [Errno -3] Temporary failure in name resolution","time":{"start":1756228271440,"stop":1756228271440,"duration":0}},{"uid":"fc0cacbb76ef49cd","reportUrl":"https://bogdanshcherban8.github.io/api_autotests/1/#testresult/fc0cacbb76ef49cd","status":"broken","statusDetails":"httpx.ConnectError: [Errno 111] Connection refused","time":{"start":1756227872327,"stop":1756227872327,"duration":0}}]},"tags":["courses","regression","create","errors"]},"source":"e9b2cad33e58ba45.json","parameterValues":["{'min_length': 1}","'estimated_time'","''","'estimatedTime'","'String should have at least 1 character'","'string_too_short'"]}